Workbook

Sheet 目標追蹤
A1: 項目 | B1: 年度目標 | C1: 已達成 | D1: 達成率 | E1: 月度目標 | F1: 本月達成 | G1: 月達成率
A2: 新簽約店家 | B2: 50 | C2: =COUNTA(已簽約店家!A2:A) | D2: =C2/B2 | E2: 4 | F2: =COUNTIFS(已簽約店家!J2:J,">="&DATE(YEAR(TODAY()),MONTH(TODAY()),1),已簽約店家!J2:J,"<"&DATE(YEAR(TODAY()),MONTH(TODAY())+1,1)) | G2: =F2/E2
A3: 場地開發 | B3: 20 | C3: =COUNTIF(場地開發!H2:H,"已確認") | D3: =C3/B3 | E3: 2 | F3: =COUNTIFS(場地開發!J2:J,">="&DATE(YEAR(TODAY()),MONTH(TODAY()),1),場地開發!J2:J,"<"&DATE(YEAR(TODAY()),MONTH(TODAY())+1,1),場地開發!H2:H,"已確認") | G3: =F3/E3
A4: 開幕店家 | B4: 40 | C4: =COUNTIF(已簽約店家!F2:F,"營運中") | D4: =C4/B4 | E4: 3 | F4: =COUNTIFS(已簽約店家!K2:K,">="&DATE(YEAR(TODAY()),MONTH(TODAY()),1),已簽約店家!F2:F,"營運中") | G4: =F4/E4

Sheet 潛在客戶
A1: 客戶名稱 | B1: 聯絡人 | C1: 電話 | D1: 地區 | E1: 階段 | F1: 負責人 | G1: 最後聯絡日 | H1: 備註
A2: 王先生物件 | B2: 王大明 | C2: 0912-345-678 | D2: 台北信義 | E2: 接近成交 | F2: 建佑 | G2: 2026-03-20 | H2: 已看場地準備簽約
A3: 李小姐物件 | B3: 李美美 | C3: 0922-111-222 | D3: 台中西屯 | E3: 有意願 | F3: 阿建 | G3: 2026-03-18 | H3: 等預算確認
A4: 張先生物件 | B4: 張三 | C4: 0933-444-555 | D4: 高雄左營 | E4: 新詢問 | F4: 大點 | G4: 2026-03-21 | H4: 初次接觸
A5: 陳小姐物件 | B5: 陳四 | C5: 0944-666-777 | D5: 桃園中壢 | E5: 接近成交 | F5: 建佑 | G5: 2026-03-19 | H5: 本週簽約
A6: 林先生物件 | B6: 林五 | C6: 0955-888-999 | D6: 台南東區 | E6: 有意願 | F6: 阿建 | G6: 2026-03-17 | H6: 場地評估中
A7: 黃先生物件 | B7: 黃六 | C7: 0966-111-222 | D7: 新竹東區 | E7: 新詢問 | F7: 大點 | G7: 2026-03-22 | H7: 剛打來詢問
A8: 吳小姐物件 | B8: 吳七 | C8: 0977-333-444 | D8: 台中北區 | E8: 有意願 | F8: 建佑 | G8: 2026-03-16 | H8: 等看場地
A9: 劉先生物件 | B9: 劉八 | C9: 0988-555-666 | D9: 台南中西 | E9: 接近成交 | F9: 阿建 | G9: 2026-03-21 | H9: 談價格中

Sheet 已簽約店家
A1: 店名 | B1: 縣市 | C1: 行政區 | D1: 地址 | E1: 品牌 | F1: 狀態 | G1: 階段 | H1: 進度% | I1: 負責人 | J1: 簽約日 | K1: 預計開幕日 | L1: 備註
A2: ONE台中西屯店 | B2: 台中市 | C2: 西屯區 | D2: 台中市西屯區中工二路123號 | E2: ONE桌遊 | F2: 籌備中 | G2: 設備安裝 | H2: 80 | I2: 建佑 | J2: 2026-01-15 | K2: 2026-04-15 | L2: 進度超前
A3: 智摸台北信義店 | B3: 台北市 | C3: 信義區 | D3: 台北市信義區信義路五段7號 | E3: 智摸 | F3: 籌備中 | G3: 裝潢施工 | H3: 60 | I3: 阿建 | J3: 2025-12-20 | K3: 2026-03-30 | L3: 進度正常
A4: ONE高雄左營店 | B4: 高雄市 | C4: 左營區 | D4: 高雄市左營區博愛二路99號 | E4: ONE桌遊 | F4: 營運中 | G4: 正式營運 | H4: 100 | I4: 大點 | J4: 2025-10-10 | K4: 2026-01-05 | L4: 營運順利
A5: ONE台北大安店 | B5: 台北市 | C5: 大安區 | D5: 台北市大安區復興南路一段222號 | E5: ONE桌遊 | F5: 已簽約 | G5: 合約簽訂 | H5: 10 | I5: 建佑 | J5: 2026-03-15 | K5: 2026-06-01 | L5: 等消防送審
A6: 智摸桃園中壢店 | B6: 桃園市 | C6: 中壢區 | D6: 桃園市中壢區中央西路二路66號 | E6: 智摸 | F6: 籌備中 | G6: 消防送審 | H6: 40 | I6: 阿建 | J6: 2026-02-01 | K6: 2026-05-15 | L6: 等審核中
A7: ONE台南東區店 | B7: 台南市 | C7: 東區 | D7: 台南市東區裕農路555號 | E7: ONE桌遊 | F7: 籌備中 | G7: 裝潢施工 | H7: 50 | I7: 大點 | J7: 2026-01-20 | K7: 2026-04-30 | L7: 進度正常
A8: ONE高雄三民店 | B8: 高雄市 | C8: 三民區 | D8: 高雄市三民區建國三路88號 | E8: ONE桌遊 | F8: 已簽約 | G8: 場地確認 | H8: 5 | I8: 建佑 | J8: 2026-03-20 | K8: 2026-07-01 | L8: 剛簽約
A9: 智摸台中北屯店 | B9: 台中市 | C9: 北屯區 | D9: 台中市北屯區崇德路二段111號 | E9: 智摸 | F9: 已簽約 | G9: 合約簽訂 | H9: 15 | I9: 阿建 | J9: 2026-03-18 | K9: 2026-06-15 | L9: 準備送審

Sheet 場地開發
A1: 場地名稱 | B1: 地址 | C1: 坪數 | D1: 租金 | E1: 屋主 | F1: 聯絡電話 | G1: 狀態 | H1: 評估結果 | I1: 負責人 | J1: 開發日期
A2: 台南東區物件A | B2: 台南市東區裕農路789號 | C2: 45 | D2: 50000 | E2: 陳先生 | F2: 0911-222-333 | G2: 評估中 | H2: 待現勘 | I2: 建佑 | J2: 2026-03-20
A3: 桃園中壢物件B | B3: 桃園市中壢區中央西路888號 | C3: 60 | D3: 65000 | E3: 林小姐 | F3: 0922-333-444 | G3: 已放棄 | H3: 租金太高 | I3: 阿建 | J3: 2026-03-15
A4: 高雄鳳山物件C | B4: 高雄市鳳山區中山路555號 | C4: 50 | D4: 48000 | E4: 王先生 | F4: 0933-555-666 | G4: 新開發 | H4: 初步評估 | I4: 大點 | J4: 2026-03-21
A5: 台北內湖物件D | B5: 台北市內湖區成功路二段123號 | C5: 55 | D5: 70000 | E5: 張小姐 | F5: 0944-777-888 | G5: 評估中 | H5: 條件不錯 | I5: 建佑 | J5: 2026-03-19
A6: 台中南屯物件E | B6: 台中市南屯區文心南路666號 | C6: 48 | D6: 52000 | E6: 李先生 | F6: 0955-999-111 | G6: 已確認 | H6: 準備簽約 | I6: 阿建 | J6: 2026-03-18
A7: 新竹東區物件F | B7: 新竹市東區光復路二段99號 | C7: 42 | D7: 45000 | E7: 黃先生 | F7: 0966-111-222 | G7: 新開發 | H7: 剛找到 | I7: 大點 | J7: 2026-03-22
A8: 台南中西物件G | B8: 台南市中西區中山路888號 | C8: 52 | D8: 55000 | E8: 吳小姐 | F8: 0977-333-444 | G8: 評估中 | H8: 等屋主回覆 | I8: 建佑 | J8: 2026-03-17

Sheet 待辦事項
A1: 任務名稱 | B1: 類型 | C1: 關聯店家/客戶 | D1: 負責人 | E1: 期限 | F1: 狀態 | G1: 優先級 | H1: 備註
A2: 台中西屯店消防檢查 | B2: 證照 | C2: ONE台中西屯店 | D2: 建佑 | E2: 2026-03-25 | F2: 進行中 | G2: 高 | H2: 已預約檢查
A3: 王先生場地現勘 | B3: 銷售 | C3: 王先生物件 | D3: 建佑 | E3: 2026-03-23 | F3: 待處理 | G3: 高 | H3: 本週完成
A4: 台北信義店設備採購 | B4: 採購 | C4: 智摸台北信義店 | D4: 阿建 | E4: 2026-03-28 | F4: 待處理 | G4: 中 | H4: 等報價單
A5: 高雄左營店開幕活動 | B5: 行銷 | C5: ONE高雄左營店 | D5: 大點 | E5: 2026-04-01 | F5: 已完成 | G5: - | H5: 已辦完
A6: 台南東區店裝潢驗收 | B6: 工程 | C6: ONE台南東區店 | D6: 大點 | E6: 2026-03-27 | F6: 進行中 | G6: 中 | H6: 預計本週完成
A7: 李小姐合約簽訂 | B7: 銷售 | C7: 李小姐物件 | D7: 阿建 | E7: 2026-03-24 | F7: 待處理 | G7: 高 | H7: 等對方確認
A8: 桃園中壢店消防送審 | B8: 證照 | C8: 智摸桃園中壢店 | D8: 阿建 | E8: 2026-03-30 | F8: 待處理 | G8: 中 | H8: 準備文件中
A9: 台北大安店設計圖 | B9: 工程 | C9: ONE台北大安店 | D9: 建佑 | E9: 2026-03-26 | F9: 進行中 | G9: 中 | H9: 設計中
A10: 陳小姐簽約準備 | B10: 銷售 | C10: 陳小姐物件 | D10: 建佑 | E10: 2026-03-25 | F10: 待處理 | G10: 高 | H10: 準備合約
A11: 高雄三民店場地勘查 | B11: 工程 | C11: ONE高雄三民店 | D11: 建佑 | E11: 2026-03-29 | F11: 待處理 | G11: 低 | H11: 初步勘查

Sheet 區域配額
A1: 縣市 | B1: 行政區 | C1: 人口數 | D1: 已開店數 | E1: 店家名稱 | F1: 特殊狀態 | G1: 備註 | H1: 配額
A2: 宜蘭縣 | B2: 宜蘭市 | C2: 94396 | D2: =COUNTIFS(已簽約店家!$B:$B,A2,已簽約店家!$C:$C,B2) | F2: 正常 | H2: 2
A3: 宜蘭縣 | B3: 羅東鎮 | C3: 68850 | D3: =COUNTIFS(已簽約店家!$B:$B,A3,已簽約店家!$C:$C,B3) | F3: 正常 | H3: 3
A4: 宜蘭縣 | B4: 冬山鄉 | C4: 52904 | D4: =COUNTIFS(已簽約店家!$B:$B,A4,已簽約店家!$C:$C,B4) | F4: 正常 | H4: 1
A5: 宜蘭縣 | B5: 五結鄉 | C5: 41757 | D5: =COUNTIFS(已簽約店家!$B:$B,A5,已簽約店家!$C:$C,B5) | F5: 正常 | H5: 1
A6: 基隆市 | B6: 中正區 | C6: 51434 | D6: =COUNTIFS(已簽約店家!$B:$B,A6,已簽約店家!$C:$C,B6) | F6: 正常 | H6: 3
A7: 新北市 | B7: 永和區 | C7: 211205 | D7: =COUNTIFS(已簽約店家!$B:$B,A7,已簽約店家!$C:$C,B7) | F7: 正常 | H7: 4
A8: 新北市 | B8: 新店區 | C8: 306636 | D8: =COUNTIFS(已簽約店家!$B:$B,A8,已簽約店家!$C:$C,B8) | F8: 正常 | H8: 5
A9: 新北市 | B9: 土城區 | C9: 242735 | D9: =COUNTIFS(已簽約店家!$B:$B,A9,已簽約店家!$C:$C,B9) | F9: 正常 | H9: 4
A10: 新北市 | B10: 中和區 | C10: 403396 | D10: =COUNTIFS(已簽約店家!$B:$B,A10,已簽約店家!$C:$C,B10) | F10: 正常 | H10: 8
A11: 新北市 | B11: 新莊區 | C11: 420922 | D11: =COUNTIFS(已簽約店家!$B:$B,A11,已簽約店家!$C:$C,B11) | F11: 正常 | H11: 7
A12: 新北市 | B12: 樹林區 | C12: 177130 | D12: =COUNTIFS(已簽約店家!$B:$B,A12,已簽約店家!$C:$C,B12) | F12: 正常 | H12: 5
A13: 新北市 | B13: 蘆洲區 | C13: 196186 | D13: =COUNTIFS(已簽約店家!$B:$B,A13,已簽約店家!$C:$C,B13) | F13: 正常 | H13: 5
... A16: 新北市 | B16: 三峽區 | C16: 115421 | D16: =COUNTIFS(已簽約店家!$B:$B,A16,已簽約店家!$C:$C,B16) | F16: 正常 | H16: 3
A17: 新北市 | B17: 三重區 | C17: 382749 | D17: =COUNTIFS(已簽約店家!$B:$B,A17,已簽約店家!$C:$C,B17) | F17: 不開放 | G17: 不開放（已授權同一業者） | H17: 5
A18: 新北市 | B18: 汐止區 | C18: 212807 | D18: =COUNTIFS(已簽約店家!$B:$B,A18,已簽約店家!$C:$C,B18) | F18: 正常 | H18: 3
A19: 新北市 | B19: 林口區 | C19: 138630 | D19: =COUNTIFS(已簽約店家!$B:$B,A19,已簽約店家!$C:$C,B19) | F19: 正常 | H19: 2
A20: 台北市 | B20: 大安區 | C20: 281679 | D20: =COUNTIFS(已簽約店家!$B:$B,A20,已簽約店家!$C:$C,B20) | F20: 正常 | H20: 3
A21: 台北市 | B21: 內湖區 | C21: 267345 | D21: =COUNTIFS(已簽約店家!$B:$B,A21,已簽約店家!$C:$C,B21) | F21: 正常 | H21: 3
A22: 台北市 | B22: 士林區 | C22: 257504 | D22: =COUNTIFS(已簽約店家!$B:$B,A22,已簽約店家!$C:$C,B22) | F22: 正常 | H22: 4
A23: 台北市 | B23: 文山區 | C23: 253272 | D23: =COUNTIFS(已簽約店家!$B:$B,A23,已簽約店家!$C:$C,B23) | F23: 正常 | H23: 4
A24: 台北市 | B24: 北投區 | C24: 235258 | D24: =COUNTIFS(已簽約店家!$B:$B,A24,已簽約店家!$C:$C,B24) | F24: 正常 | H24: 3
A25: 台北市 | B25: 中山區 | C25: 211649 | D25: =COUNTIFS(已簽約店家!$B:$B,A25,已簽約店家!$C:$C,B25) | F25: 正常 | H25: 4
A26: 台北市 | B26: 信義區 | C26: 201012 | D26: =COUNTIFS(已簽約店家!$B:$B,A26,已簽約店家!$C:$C,B26) | F26: 正常 | H26: 3
A27: 台北市 | B27: 松山區 | C27: 187065 | D27: =COUNTIFS(已簽約店家!$B:$B,A27,已簽約店家!$C:$C,B27) | F27: 正常 | H27: 2
A28: 台北市 | B28: 萬華區 | C28: 168261 | D28: =COUNTIFS(已簽約店家!$B:$B,A28,已簽約店家!$C:$C,B28) | F28: 正常 | H28: 2
A29: 台北市 | B29: 中正區 | C29: 143821 | D29: =COUNTIFS(已簽約店家!$B:$B,A29,已簽約店家!$C:$C,B29) | F29: 正常 | H29: 3
... A44: 新竹縣 | B44: 新豐鄉 | C44: 59877 | D44: =COUNTIFS(已簽約店家!$B:$B,A44,已簽約店家!$C:$C,B44) | F44: 正常 | H44: 3
A45: 新竹縣 | B45: 竹北市 | C45: 221005 | D45: =COUNTIFS(已簽約店家!$B:$B,A45,已簽約店家!$C:$C,B45) | F45: 不開放 | G45: 舊約額滿 | H45: 6
A46: 新竹縣 | B46: 竹東鎮 | C46: 97844 | D46: =COUNTIFS(已簽約店家!$B:$B,A46,已簽約店家!$C:$C,B46) | F46: 正常 | H46: 2
A47: 苗栗縣 | B47: 頭份市 | C47: 108294 | D47: =COUNTIFS(已簽約店家!$B:$B,A47,已簽約店家!$C:$C,B47) | F47: 不開放 | G47: 舊約額滿 | H47: 4
A48: 苗栗縣 | B48: 竹南鎮 | C48: 91494 | D48: =COUNTIFS(已簽約店家!$B:$B,A48,已簽約店家!$C:$C,B48) | F48: 不開放 | G48: 保留不開放 | H48: 1
A49: 苗栗縣 | B49: 苗栗市 | C49: 85671 | D49: =COUNTIFS(已簽約店家!$B:$B,A49,已簽約店家!$C:$C,B49) | F49: 正常 | H49: 1
A50: 苗栗縣 | B50: 苑里鎮 | C50: 43139 | D50: =COUNTIFS(已簽約店家!$B:$B,A50,已簽約店家!$C:$C,B50) | F50: 正常 | H50: 1
A51: 台中市 | B51: 北屯區 | C51: 317532 | D51: =COUNTIFS(已簽約店家!$B:$B,A51,已簽約店家!$C:$C,B51) | F51: 正常 | H51: 4
A52: 台中市 | B52: 西屯區 | C52: 237978 | D52: =COUNTIFS(已簽約店家!$B:$B,A52,已簽約店家!$C:$C,B52) | F52: 正常 | H52: 4
A53: 台中市 | B53: 大里區 | C53: 210922 | D53: =COUNTIFS(已簽約店家!$B:$B,A53,已簽約店家!$C:$C,B53) | F53: 正常 | H53: 3
A54: 台中市 | B54: 太平區 | C54: 201696 | D54: =COUNTIFS(已簽約店家!$B:$B,A54,已簽約店家!$C:$C,B54) | F54: 正常 | H54: 3
A55: 台中市 | B55: 南屯區 | C55: 186106 | D55: =COUNTIFS(已簽約店家!$B:$B,A55,已簽約店家!$C:$C,B55) | F55: 正常 | H55: 2
A56: 台中市 | B56: 豐原區 | C56: 161597 | D56: =COUNTIFS(已簽約店家!$B:$B,A56,已簽約店家!$C:$C,B56) | F56: 正常 | H56: 2
...
